<?xml version="1.0" ?>
<robot name="jimmbot" xmlns:xacro="http://www.ros.org/wiki/xacro">

<xacro:include filename="$(find jimmbot_description)/urdf/materials.xacro" />
<xacro:include filename="$(find jimmbot_description)/urdf/jimmbot.trans" />
<xacro:include filename="$(find jimmbot_description)/urdf/jimmbot.gazebo" />

<!-- Inertial matrixes -->
<xacro:macro name="base_link_inertial" params="mass">
  <inertial>
    <mass value="${mass}"/>
    <inertia 
              ixx="6.994E+08" 
              ixy="3.083E+05" 
              ixz="-2.746E+05" 
              iyy="1.202E+09" 
              iyz="-6.256E+05" 
              izz="1.446E+09" />
  </inertial>
</xacro:macro>

<xacro:macro name="boggie_inertial" params="mass">
  <inertial>
    <mass value="${mass}"/>
    <inertia 
              ixx="1.327E+07" 
              ixy="-1.417E+04" 
              ixz="-4.374E+05" 
              iyy="2.052E+08" 
              iyz="-1.830E+06" 
              izz="1.947E+08" />
  </inertial>
</xacro:macro>

<xacro:macro name="wheel_axis_inertial" params="mass">
  <inertial>
    <mass value="${mass}"/>
    <inertia 
              ixx="4.476E+04" 
              ixy="-1.834E+05" 
              ixz="-1.686E+05" 
              iyy="1.446E+06" 
              iyz="-2.198E+04" 
              izz="1.450E+06" />
  </inertial>
</xacro:macro>

<xacro:macro name="wheel_inertial" params="mass">
  <inertial>
    <mass value="${mass}"/>
    <inertia 
              ixx="4.654E+06" 
              ixy="-7.410E+06" 
              ixz="-6.730E+06" 
              iyy="5.291E+07" 
              iyz="-9.714E+05" 
              izz="5.309E+07" />
  </inertial>
</xacro:macro>
<!-- end Inertial matrixes -->

<!-- base_link -->
<link name="base_link">
  <visual>
    <origin rpy="0 0 0" xyz="0 0 0"/>
    <geometry>
        <mesh filename="package://jimmbot_description/meshes/base_link/base_link.stl" scale="0.001 0.001 0.001"/>
      </geometry>
      <material name="silver"/>
    </visual>
  <collision>
    <origin rpy="0 0 0" xyz="0 0 0"/>
    <geometry>
        <mesh filename="package://jimmbot_description/meshes/base_link/base_link.stl" scale="0.001 0.001 0.001"/>
    </geometry>
  </collision>
  <xacro:base_link_inertial mass="40.0"/>
</link>
<!-- end base_link -->

<!-- boggies -->
<xacro:macro name="boggie" params="postfix reflect">
    <link name="boggie_${postfix}">
        <visual>
            <origin rpy="0 0 0" xyz="0 0 0"/>
            <geometry>
                <mesh filename="package://jimmbot_description/meshes/boggie/boggie.stl" scale="0.001 0.001 0.001"/>
            </geometry>
            <material name="silver"/>
        </visual>
        <collision>
            <origin rpy="0 0 0" xyz="0 0 0"/>
            <geometry>
                <mesh filename="package://jimmbot_description/meshes/boggie/boggie.stl" scale="0.001 0.001 0.001"/>
            </geometry>
        </collision>
        <xacro:boggie_inertial mass="6.0"/>
    </link>

    <joint name="base_to_boggie_${postfix}" type="revolute">
        <axis xyz="1 0 0"/>
        <limit effort="1000.0" lower="-0.523599" upper="0.523599" velocity="50"/>
        <origin rpy="0 0 ${reflect*-1.57}" xyz="0 ${reflect*0.3} 0"/>
        <parent link="base_link"/>
        <child link="boggie_${postfix}"/>
    </joint>
</xacro:macro>
<xacro:boggie postfix="right" reflect="-1" />
<xacro:boggie postfix="left" reflect="1" />
<!-- end boggies -->

<!-- wheels -->
<xacro:macro name="wheel" params="side boggie reflect upsidedown">
    <link name="wheel_axis_${side}_${boggie}">
        <visual>
            <origin rpy="0 0 0" xyz="0 0 0"/>
            <geometry>
                <mesh filename="package://jimmbot_description/meshes/wheel/wheel_axis.stl" scale="0.001 0.001 0.001"/>
            </geometry>
            <material name="silver"/>
        </visual>
        <collision>
            <origin rpy="0 0 0" xyz="0 0 0"/>
            <geometry>
                <mesh filename="package://jimmbot_description/meshes/wheel/wheel_axis.stl" scale="0.001 0.001 0.001"/>
            </geometry>
        </collision>
        <xacro:wheel_axis_inertial mass="0.039"/>
    </link>

    <link name="wheel_${side}_${boggie}">
        <visual>
            <origin rpy="0 0 0" xyz="0 0 0"/>
            <geometry>
                <mesh filename="package://jimmbot_description/meshes/wheel/wheel.stl" scale="0.001 0.001 0.001"/>
            </geometry>
            <material name="silver"/>
        </visual>
        <collision>
            <origin rpy="0 0 0" xyz="0 0 0"/>
            <geometry>
                <mesh filename="package://jimmbot_description/meshes/wheel/wheel.stl" scale="0.001 0.001 0.001"/>
            </geometry>
        </collision>
        <xacro:wheel_inertial mass="1.0"/>
    </link>

    <joint name="wheel_to_wheel_axis_${side}_${boggie}" type="fixed">
        <origin rpy="0 0 ${reflect*3.14}" xyz="0 ${reflect*upsidedown*0.2} 0"/>
        <parent link="boggie_${boggie}"/>
        <child link="wheel_axis_${side}_${boggie}"/>
    </joint>

    <joint name="wheel_axis_to_wheel_holder_${side}_${boggie}" type="continuous">
        <origin rpy="0 0 0" xyz="0 0 0"/>
        <parent link="wheel_axis_${side}_${boggie}"/>
        <child link="wheel_${side}_${boggie}"/>
    </joint>
</xacro:macro>
<xacro:wheel side="front" boggie="left" reflect="1" upsidedown="1" />
<xacro:wheel side="front" boggie="right" reflect="-1" upsidedown="1" />
<xacro:wheel side="back" boggie="left" reflect="1" upsidedown="-1" />
<xacro:wheel side="back" boggie="right" reflect="-1" upsidedown="-1" />
<!-- end wheels -->

</robot>