<?xml version="1.0" encoding="utf-8"?>
<!-- =================================================================================== -->
<!-- |    This document was autogenerated by xacro from /home/jimmyhalimi/ws/jimmBOT_ws/src/jimmbot_description/urdf/jimmbot.xacro | -->
<!-- |    EDITING THIS FILE BY HAND IS NOT RECOMMENDED                                 | -->
<!-- =================================================================================== -->
<robot name="jimmbot">
  <material name="silver">
    <color rgba="0.700 0.700 0.700 1.000"/>
  </material>
  <gazebo>
    <plugin filename="libgazebo_ros_control.so" name="control"/>
  </gazebo>
  <gazebo reference="base_link">
    <material>Gazebo/Silver</material>
    <mu1>0.2</mu1>
    <mu2>0.2</mu2>
    <selfCollide>true</selfCollide>
    <gravity>true</gravity>
  </gazebo>
  <!-- end Inertial matrixes -->
  <!-- dummy base_link -->
  <link name="base_link"/>
  <joint name="base_link_to_chassis" type="fixed">
    <parent link="base_link"/>
    <child link="chassis"/>
  </joint>
  <!-- end dummy base_link -->
  <!-- chassis -->
  <link name="chassis">
    <visual>
      <origin rpy="0 0 0" xyz="0 0 0"/>
      <geometry>
        <mesh filename="package://jimmbot_description/meshes/chassis/chassis.stl" scale="0.001 0.001 0.001"/>
      </geometry>
      <material name="silver"/>
    </visual>
    <collision>
      <origin rpy="0 0 0" xyz="0 0 0"/>
      <geometry>
        <mesh filename="package://jimmbot_description/meshes/chassis/chassis.stl" scale="0.001 0.001 0.001"/>
      </geometry>
    </collision>
    <inertial>
      <mass value="40.0"/>
      <inertia ixx="6.994E+08" ixy="3.083E+05" ixz="-2.746E+05" iyy="1.202E+09" iyz="-6.256E+05" izz="1.446E+09"/>
    </inertial>
  </link>
  <!-- end chassis -->
  <link name="boggie_right">
    <visual>
      <origin rpy="0 0 0" xyz="0 0 0"/>
      <geometry>
        <mesh filename="package://jimmbot_description/meshes/boggie/boggie.stl" scale="0.001 0.001 0.001"/>
      </geometry>
      <material name="silver"/>
    </visual>
    <collision>
      <origin rpy="0 0 0" xyz="0 0 0"/>
      <geometry>
        <mesh filename="package://jimmbot_description/meshes/boggie/boggie.stl" scale="0.001 0.001 0.001"/>
      </geometry>
    </collision>
    <inertial>
      <mass value="6.0"/>
      <inertia ixx="1.327E+07" ixy="-1.417E+04" ixz="-4.374E+05" iyy="2.052E+08" iyz="-1.830E+06" izz="1.947E+08"/>
    </inertial>
  </link>
  <joint name="chassis_to_boggie_right" type="revolute">
    <axis xyz="-1 0 0"/>
    <limit effort="1000.0" lower="-0.523599" upper="0.523599" velocity="50"/>
    <origin rpy="0 0 1.57" xyz="-1.45758E-03 -0.201552 -19.8088E-03"/>
    <parent link="chassis"/>
    <child link="boggie_right"/>
  </joint>
  <link name="boggie_left">
    <visual>
      <origin rpy="0 0 0" xyz="0 0 0"/>
      <geometry>
        <mesh filename="package://jimmbot_description/meshes/boggie/boggie.stl" scale="0.001 0.001 0.001"/>
      </geometry>
      <material name="silver"/>
    </visual>
    <collision>
      <origin rpy="0 0 0" xyz="0 0 0"/>
      <geometry>
        <mesh filename="package://jimmbot_description/meshes/boggie/boggie.stl" scale="0.001 0.001 0.001"/>
      </geometry>
    </collision>
    <inertial>
      <mass value="6.0"/>
      <inertia ixx="1.327E+07" ixy="-1.417E+04" ixz="-4.374E+05" iyy="2.052E+08" iyz="-1.830E+06" izz="1.947E+08"/>
    </inertial>
  </link>
  <joint name="chassis_to_boggie_left" type="revolute">
    <axis xyz="1 0 0"/>
    <limit effort="1000.0" lower="-0.523599" upper="0.523599" velocity="50"/>
    <origin rpy="0 0 -1.57" xyz="-1.45758E-03 0.201552 -19.8088E-03"/>
    <parent link="chassis"/>
    <child link="boggie_left"/>
  </joint>
  <!-- end boggies -->
  <link name="wheel_axis_front_left">
    <visual>
      <origin rpy="0 0 0" xyz="0 0 0"/>
      <geometry>
        <mesh filename="package://jimmbot_description/meshes/wheel/wheel_axis.stl" scale="0.001 0.001 0.001"/>
      </geometry>
      <material name="silver"/>
    </visual>
    <collision>
      <origin rpy="0 0 0" xyz="0 0 0"/>
      <geometry>
        <mesh filename="package://jimmbot_description/meshes/wheel/wheel_axis.stl" scale="0.001 0.001 0.001"/>
      </geometry>
    </collision>
    <inertial>
      <mass value="0.039"/>
      <inertia ixx="4.476E+04" ixy="-1.834E+05" ixz="-1.686E+05" iyy="1.446E+06" iyz="-2.198E+04" izz="1.450E+06"/>
    </inertial>
  </link>
  <link name="wheel_front_left">
    <visual>
      <origin rpy="0 0 0" xyz="0 0 0"/>
      <geometry>
        <mesh filename="package://jimmbot_description/meshes/wheel/wheel.stl" scale="0.001 0.001 0.001"/>
      </geometry>
      <material name="silver"/>
    </visual>
    <collision>
      <origin rpy="0 0 0" xyz="0 0 0"/>
      <geometry>
        <mesh filename="package://jimmbot_description/meshes/wheel/wheel.stl" scale="0.001 0.001 0.001"/>
      </geometry>
    </collision>
    <inertial>
      <mass value="1.0"/>
      <inertia ixx="4.654E+06" ixy="-7.410E+06" ixz="-6.730E+06" iyy="5.291E+07" iyz="-9.714E+05" izz="5.309E+07"/>
    </inertial>
  </link>
  <joint name="boggie_left_to_wheel_axis_front_left" type="fixed">
    <origin rpy="0.785398 0 3.14" xyz="-0.04 0.290414 -70.2315E-03"/>
    <parent link="boggie_left"/>
    <child link="wheel_axis_front_left"/>
  </joint>
  <joint name="wheel_axis_front_left_to_wheel_front_left" type="continuous">
    <axis xyz="1 0 0"/>
    <origin rpy="0 0 0" xyz="0 0 0"/>
    <parent link="wheel_axis_front_left"/>
    <child link="wheel_front_left"/>
  </joint>
  <link name="wheel_axis_front_right">
    <visual>
      <origin rpy="0 0 0" xyz="0 0 0"/>
      <geometry>
        <mesh filename="package://jimmbot_description/meshes/wheel/wheel_axis.stl" scale="0.001 0.001 0.001"/>
      </geometry>
      <material name="silver"/>
    </visual>
    <collision>
      <origin rpy="0 0 0" xyz="0 0 0"/>
      <geometry>
        <mesh filename="package://jimmbot_description/meshes/wheel/wheel_axis.stl" scale="0.001 0.001 0.001"/>
      </geometry>
    </collision>
    <inertial>
      <mass value="0.039"/>
      <inertia ixx="4.476E+04" ixy="-1.834E+05" ixz="-1.686E+05" iyy="1.446E+06" iyz="-2.198E+04" izz="1.450E+06"/>
    </inertial>
  </link>
  <link name="wheel_front_right">
    <visual>
      <origin rpy="0 0 0" xyz="0 0 0"/>
      <geometry>
        <mesh filename="package://jimmbot_description/meshes/wheel/wheel.stl" scale="0.001 0.001 0.001"/>
      </geometry>
      <material name="silver"/>
    </visual>
    <collision>
      <origin rpy="0 0 0" xyz="0 0 0"/>
      <geometry>
        <mesh filename="package://jimmbot_description/meshes/wheel/wheel.stl" scale="0.001 0.001 0.001"/>
      </geometry>
    </collision>
    <inertial>
      <mass value="1.0"/>
      <inertia ixx="4.654E+06" ixy="-7.410E+06" ixz="-6.730E+06" iyy="5.291E+07" iyz="-9.714E+05" izz="5.309E+07"/>
    </inertial>
  </link>
  <joint name="boggie_right_to_wheel_axis_front_right" type="fixed">
    <origin rpy="-0.785398 0 -3.14" xyz="-0.04 -0.290414 -70.2315E-03"/>
    <parent link="boggie_right"/>
    <child link="wheel_axis_front_right"/>
  </joint>
  <joint name="wheel_axis_front_right_to_wheel_front_right" type="continuous">
    <axis xyz="-1 0 0"/>
    <origin rpy="0 0 0" xyz="0 0 0"/>
    <parent link="wheel_axis_front_right"/>
    <child link="wheel_front_right"/>
  </joint>
  <link name="wheel_axis_back_left">
    <visual>
      <origin rpy="0 0 0" xyz="0 0 0"/>
      <geometry>
        <mesh filename="package://jimmbot_description/meshes/wheel/wheel_axis.stl" scale="0.001 0.001 0.001"/>
      </geometry>
      <material name="silver"/>
    </visual>
    <collision>
      <origin rpy="0 0 0" xyz="0 0 0"/>
      <geometry>
        <mesh filename="package://jimmbot_description/meshes/wheel/wheel_axis.stl" scale="0.001 0.001 0.001"/>
      </geometry>
    </collision>
    <inertial>
      <mass value="0.039"/>
      <inertia ixx="4.476E+04" ixy="-1.834E+05" ixz="-1.686E+05" iyy="1.446E+06" iyz="-2.198E+04" izz="1.450E+06"/>
    </inertial>
  </link>
  <link name="wheel_back_left">
    <visual>
      <origin rpy="0 0 0" xyz="0 0 0"/>
      <geometry>
        <mesh filename="package://jimmbot_description/meshes/wheel/wheel.stl" scale="0.001 0.001 0.001"/>
      </geometry>
      <material name="silver"/>
    </visual>
    <collision>
      <origin rpy="0 0 0" xyz="0 0 0"/>
      <geometry>
        <mesh filename="package://jimmbot_description/meshes/wheel/wheel.stl" scale="0.001 0.001 0.001"/>
      </geometry>
    </collision>
    <inertial>
      <mass value="1.0"/>
      <inertia ixx="4.654E+06" ixy="-7.410E+06" ixz="-6.730E+06" iyy="5.291E+07" iyz="-9.714E+05" izz="5.309E+07"/>
    </inertial>
  </link>
  <joint name="boggie_left_to_wheel_axis_back_left" type="fixed">
    <origin rpy="-0.785398 0 -3.14" xyz="-0.04 -0.290414 -70.2315E-03"/>
    <parent link="boggie_left"/>
    <child link="wheel_axis_back_left"/>
  </joint>
  <joint name="wheel_axis_back_left_to_wheel_back_left" type="continuous">
    <axis xyz="1 0 0"/>
    <origin rpy="0 0 0" xyz="0 0 0"/>
    <parent link="wheel_axis_back_left"/>
    <child link="wheel_back_left"/>
  </joint>
  <link name="wheel_axis_back_right">
    <visual>
      <origin rpy="0 0 0" xyz="0 0 0"/>
      <geometry>
        <mesh filename="package://jimmbot_description/meshes/wheel/wheel_axis.stl" scale="0.001 0.001 0.001"/>
      </geometry>
      <material name="silver"/>
    </visual>
    <collision>
      <origin rpy="0 0 0" xyz="0 0 0"/>
      <geometry>
        <mesh filename="package://jimmbot_description/meshes/wheel/wheel_axis.stl" scale="0.001 0.001 0.001"/>
      </geometry>
    </collision>
    <inertial>
      <mass value="0.039"/>
      <inertia ixx="4.476E+04" ixy="-1.834E+05" ixz="-1.686E+05" iyy="1.446E+06" iyz="-2.198E+04" izz="1.450E+06"/>
    </inertial>
  </link>
  <link name="wheel_back_right">
    <visual>
      <origin rpy="0 0 0" xyz="0 0 0"/>
      <geometry>
        <mesh filename="package://jimmbot_description/meshes/wheel/wheel.stl" scale="0.001 0.001 0.001"/>
      </geometry>
      <material name="silver"/>
    </visual>
    <collision>
      <origin rpy="0 0 0" xyz="0 0 0"/>
      <geometry>
        <mesh filename="package://jimmbot_description/meshes/wheel/wheel.stl" scale="0.001 0.001 0.001"/>
      </geometry>
    </collision>
    <inertial>
      <mass value="1.0"/>
      <inertia ixx="4.654E+06" ixy="-7.410E+06" ixz="-6.730E+06" iyy="5.291E+07" iyz="-9.714E+05" izz="5.309E+07"/>
    </inertial>
  </link>
  <joint name="boggie_right_to_wheel_axis_back_right" type="fixed">
    <origin rpy="0.785398 0 3.14" xyz="-0.04 0.290414 -70.2315E-03"/>
    <parent link="boggie_right"/>
    <child link="wheel_axis_back_right"/>
  </joint>
  <joint name="wheel_axis_back_right_to_wheel_back_right" type="continuous">
    <axis xyz="-1 0 0"/>
    <origin rpy="0 0 0" xyz="0 0 0"/>
    <parent link="wheel_axis_back_right"/>
    <child link="wheel_back_right"/>
  </joint>
  <!-- end wheels -->
</robot>

