<?xml version="1.0" ?>
<robot name="jimmbot" xmlns:xacro="http://www.ros.org/wiki/xacro">

<xacro:include filename="$(find jimmbot_description)/urdf/materials.xacro" />
<xacro:include filename="$(find jimmbot_description)/urdf/jimmbot.trans" />
<xacro:include filename="$(find jimmbot_description)/urdf/jimmbot.gazebo" />

<!-- Inertial matrixes -->
<xacro:macro name="chassis_inertial" params="mass">
  <inertial>
    <mass value="${mass}"/>
    <inertia 
              ixx="6.994E+08" 
              ixy="3.083E+05" 
              ixz="-2.746E+05" 
              iyy="1.202E+09" 
              iyz="-6.256E+05" 
              izz="1.446E+09" />
  </inertial>
</xacro:macro>

<xacro:macro name="boggie_inertial" params="mass">
  <inertial>
    <mass value="${mass}"/>
    <inertia 
              ixx="1.327E+07" 
              ixy="-1.417E+04" 
              ixz="-4.374E+05" 
              iyy="2.052E+08" 
              iyz="-1.830E+06" 
              izz="1.947E+08" />
  </inertial>
</xacro:macro>

<xacro:macro name="wheel_axis_inertial" params="mass">
  <inertial>
    <mass value="${mass}"/>
    <inertia 
              ixx="4.476E+04" 
              ixy="-1.834E+05" 
              ixz="-1.686E+05" 
              iyy="1.446E+06" 
              iyz="-2.198E+04" 
              izz="1.450E+06" />
  </inertial>
</xacro:macro>

<xacro:macro name="wheel_inertial" params="mass">
  <inertial>
    <mass value="${mass}"/>
    <inertia 
              ixx="4.654E+06" 
              ixy="-7.410E+06" 
              ixz="-6.730E+06" 
              iyy="5.291E+07" 
              iyz="-9.714E+05" 
              izz="5.309E+07" />
  </inertial>
</xacro:macro>
<!-- end Inertial matrixes -->

<!-- dummy base_link -->
<link name="base_link" />

<joint name="base_link_to_chassis" type="fixed">
  <parent link="base_link"/>
  <child link="chassis"/>
</joint>
<!-- end dummy base_link -->

<!-- chassis -->
<link name="chassis">
  <visual>
    <origin rpy="0 0 0" xyz="0 0 0"/>
    <geometry>
        <mesh filename="package://jimmbot_description/meshes/chassis/chassis.stl" scale="0.001 0.001 0.001"/>
      </geometry>
      <material name="silver"/>
    </visual>
  <collision>
    <origin rpy="0 0 0" xyz="0 0 0"/>
    <geometry>
        <mesh filename="package://jimmbot_description/meshes/chassis/chassis.stl" scale="0.001 0.001 0.001"/>
    </geometry>
  </collision>
  <xacro:chassis_inertial mass="40.0"/>
</link>
<!-- end chassis -->

<!-- boggies -->
<xacro:macro name="boggie" params="postfix reflect">
    <link name="boggie_${postfix}">
        <visual>
            <origin rpy="0 0 0" xyz="0 0 0"/>
            <geometry>
                <mesh filename="package://jimmbot_description/meshes/boggie/boggie.stl" scale="0.001 0.001 0.001"/>
            </geometry>
            <material name="silver"/>
        </visual>
        <collision>
            <origin rpy="0 0 0" xyz="0 0 0"/>
            <geometry>
                <mesh filename="package://jimmbot_description/meshes/boggie/boggie.stl" scale="0.001 0.001 0.001"/>
            </geometry>
        </collision>
        <xacro:boggie_inertial mass="6.0"/>
    </link>

    <joint name="chassis_to_boggie_${postfix}" type="revolute">
        <axis xyz="${reflect*-1} 0 0"/>
        <limit effort="1000.0" lower="-0.523599" upper="0.523599" velocity="50"/>
        <origin rpy="0 0 ${reflect*1.57}" xyz="-1.45758E-03 ${reflect*-201.552E-03} -19.8088E-03"/>
        <parent link="chassis"/>
        <child link="boggie_${postfix}"/>
    </joint>
</xacro:macro>
<xacro:boggie postfix="right" reflect="1"/>
<xacro:boggie postfix="left" reflect="-1"/>
<!-- end boggies -->

<!-- wheels -->
<xacro:macro name="wheel" params="side boggie reflect across rotation">
    <link name="wheel_axis_${side}_${boggie}">
        <visual>
            <origin rpy="0 0 0" xyz="0 0 0"/>
            <geometry>
                <mesh filename="package://jimmbot_description/meshes/wheel/wheel_axis.stl" scale="0.001 0.001 0.001"/>
            </geometry>
            <material name="silver"/>
        </visual>
        <collision>
            <origin rpy="0 0 0" xyz="0 0 0"/>
            <geometry>
                <mesh filename="package://jimmbot_description/meshes/wheel/wheel_axis.stl" scale="0.001 0.001 0.001"/>
            </geometry>
        </collision>
        <xacro:wheel_axis_inertial mass="0.039"/>
    </link>

    <link name="wheel_${side}_${boggie}">
        <visual>
            <origin rpy="0 0 0" xyz="0 0 0"/>
            <geometry>
                <mesh filename="package://jimmbot_description/meshes/wheel/wheel.stl" scale="0.001 0.001 0.001"/>
            </geometry>
            <material name="silver"/>
        </visual>
        <collision>
            <origin rpy="0 0 0" xyz="0 0 0"/>
            <geometry>
                <mesh filename="package://jimmbot_description/meshes/wheel/wheel.stl" scale="0.001 0.001 0.001"/>
            </geometry>
        </collision>
        <xacro:wheel_inertial mass="1.0"/>
    </link>

    <joint name="boggie_${boggie}_to_wheel_axis_${side}_${boggie}" type="fixed">
        <origin rpy="${reflect*across*-0.785398} 0 ${reflect*across*-3.14}" xyz="${reflect*-40.000E-03} ${across*-290.414E-03} -70.2315E-03"/>
        <parent link="boggie_${boggie}"/>
        <child link="wheel_axis_${side}_${boggie}"/>
    </joint>

    <joint name="wheel_axis_${side}_${boggie}_to_wheel_${side}_${boggie}" type="continuous">
        <axis xyz="${rotation} 0 0"/>
        <origin rpy="0 0 0" xyz="0 0 0"/>
        <parent link="wheel_axis_${side}_${boggie}"/>
        <child link="wheel_${side}_${boggie}"/>
    </joint>
</xacro:macro>
<xacro:wheel side="front" boggie="left" across="-1" reflect="1" rotation="1"/>
<xacro:wheel side="front" boggie="right" across="1" reflect="1" rotation="-1"/>
<xacro:wheel side="back" boggie="left" across="1" reflect="1" rotation="1"/>
<xacro:wheel side="back" boggie="right" across="-1" reflect="1" rotation="-1"/>
<!-- end wheels -->

</robot>